<!-- Cartpole Model
    The state space is populated with joints in the order that they are
    defined in this file. The actuators also operate on joints.

    State-Space (name/joint/parameter):
        - cart      slider      position (m)
        - pole      hinge       angle (rad)
        - cart      slider      velocity (m/s)
        - pole      hinge       angular velocity (rad/s)

    Actuators (name/actuator/parameter):
        - cart      motor       force x (N)
-->
<mujoco model="cartpole">
  <compiler coordinate="local" inertiafromgeom="true"/>
  <custom>
    <numeric data="2" name="frame_skip"/>
  </custom>
  <default>
    <joint damping="0.05"/>
    <geom contype="0" friction="1 0.1 0.1" rgba="0.7 0.7 0 1"/>
  </default>
  <option gravity="0 0 -9.81" integrator="RK4" timestep="0.01"/>
  <size nstack="3000"/>
  <worldbody>
    <geom name="floor" pos="0 0 -3.0" rgba="0.8 0.9 0.8 1" size="40 40 40" type="plane"/>
    <geom name="rail" pos="0 0 0" quat="0.707 0 0.707 0" rgba="1 0.3 0.3 1" size="0.02 1" type="capsule"/>
    <body name="cart" pos="0 0 0">
      <joint axis="1 0 0" limited="true" margin="0.01" name="slider" pos="0 0 0" range="-1 1" type="slide"/>
      <geom name="cart" pos="0 0 0" quat="0.707 0 0.707 0" size="0.08 0.08" type="capsule"/>
      <body name="pole" pos="0 0 0">
        <joint axis="0 1 0" name="hinge" pos="0 0 0" type="hinge"/>
        <geom fromto="0 0 0 0 0 0.3" name="cpole" rgba="0.8 1.4 1.4 1" size="0.045 0.3" type="capsule"/>
        <site name="tip1" pos="0 0 .3" size="0.05 0.05" type="sphere"/>
        <body name="pole2" pos="0 0 0.3">
          <joint axis="0 1 0" name="hinge2" pos="0 0 0" type="hinge"/>
          <geom fromto="0 0 0 0 0 0.3" name="cpole2" rgba="0.8 1.4 1.4 1" size="0.045 0.3" type="capsule"/>
          <site name="tip2" pos="0 0 .3" size="0.05 0.05" type="sphere"/>
          <body name="pole3" pos="0 0 0.3">
            <joint axis="0 1 0" name="hinge3" pos="0 0 0" type="hinge"/>
            <geom fromto="0 0 0 0 0 0.3" name="cpole3" rgba="0.8 1.4 1.4 1" size="0.045 0.3" type="capsule"/>
            <site name="tip3" pos="0 0 .3" size="0.05 0.05" type="sphere"/>
            <body name="pole4" pos="0 0 0.3">
              <joint axis="0 1 0" name="hinge4" pos="0 0 0" type="hinge"/>
              <geom fromto="0 0 0 0 0 0.3" name="cpole4" rgba="0.8 1.4 1.4 1" size="0.045 0.3" type="capsule"/>
              <site name="tip4" pos="0 0 .3" size="0.01 0.01" type="sphere"/>
            </body>
          </body>
        </body>
      </body>
    </body>
  </worldbody>
  <actuator>
    <motor ctrllimited="true" ctrlrange="-1 1" gear="500" joint="slider" name="slide"/>
  </actuator>
</mujoco>
